<?xml version="1.0" ?>
<!-- =================================================================================== -->
<!-- |    This document was autogenerated by xacro from my_robot.urdf.xacro            | -->
<!-- |    EDITING THIS FILE BY HAND IS NOT RECOMMENDED                                 | -->
<!-- =================================================================================== -->
<robot name="robot">
  <!-- <xacro:include filename="$(find robot_description)/urdf/gazebo.urdf.xacro" /> -->
  <!-- Define robot constants -->
  <!-- Values order for is: length, width, height -->
  <!-- ~~~~~~~~~~~~~~~ -->
  <!-- INERTIAL MACROS -->
  <!-- ~~~~~~~~~~~~~~~ -->
  <!-- ~~~~~ -->
  <!-- LINKS -->
  <!-- ~~~~~ -->
  <!-- LIMIT CYLINDER -->
  <!-- <link name="cylinder">
        <visual>
            <geometry>
                <cylinder radius="1.05" length="2.5"/>
            </geometry>
            <material name="Wood">
                <color rgba="0.58 0.46 0.18 0.3"/>
            </material>
        </visual>
    </link> -->
  <!-- BOAT -->
  <link name="bottom_link">
    <visual>
      <geometry>
        <box size="0.48 0.32 0.04"/>
      </geometry>
      <material name="Wood">
        <color rgba="0.58 0.46 0.18 1.0"/>
      </material>
    </visual>
    <collision>
      <geometry>
        <box size="0.48 0.32 0.04"/>
      </geometry>
    </collision>
  </link>
  <inertial>
    <origin rpy="0 0 0" xyz="0 0 0"/>
    <mass value="1"/>
    <inertia ixx="0.008666666666666666" ixy="0.0" ixz="0.0" iyy="0.027733333333333332" iyz="0.0" izz="0.01933333333333333"/>
    <!-- <inertia ixx="${(m/12) * (size[2]*size[2] + size[0]*size[0])}" ixy="0.0" ixz="0.0" iyy="${(m/12) * (size[1]*size[1] + size[0]*size[0])}" iyz="0.0" izz="${(m/12) * (size[1]*size[1] + size[2]*size[2])}"/> -->
  </inertial>
  <!-- PIG -->
  <link name="body_link">
    <visual>
      <geometry>
        <box size="0.32 0.20 0.16"/>
      </geometry>
      <material name="Pink">
        <color rgba="0.88 0.26 0.26 1.0"/>
      </material>
    </visual>
    <collision>
      <geometry>
        <box size="0.32 0.20 0.16"/>
      </geometry>
    </collision>
  </link>
  <link name="head_link">
    <visual>
      <geometry>
        <box size="0.16 0.16 0.16"/>
      </geometry>
      <material name="Pink">
        <color rgba="0.859 0.318 0.318 1.0"/>
      </material>
    </visual>
    <collision>
      <geometry>
        <box size="0.16 0.16 0.16"/>
      </geometry>
    </collision>
  </link>
  <link name="nose_link">
    <visual>
      <geometry>
        <box size="0.02 0.08 0.06"/>
      </geometry>
      <material name="Pink">
        <color rgba="0.75 0.20 0.20 1.0"/>
      </material>
    </visual>
    <collision>
      <geometry>
        <box size="0.02 0.08 0.06"/>
      </geometry>
    </collision>
  </link>
  <!-- Caster wheel -->
  <link name="base_footprint"/>
  <joint name="footprint_joint" type="fixed">
    <parent link="bottom_link"/>
    <child link="base_footprint"/>
    <origin rpy="0 0 0" xyz="0.0 0.0 -0.08"/>
  </joint>
  <link name="caster_wheel_link">
    <visual>
      <geometry>
        <sphere radius="0.04"/>
      </geometry>
      <material name="Dark Wood">
        <color rgba="0.46 0.36 0.10 1.0"/>
      </material>
    </visual>
    <collision>
      <geometry>
        <sphere radius="0.04"/>
      </geometry>
    </collision>
  </link>
  <joint name="caster_wheel_joint" type="continuous">
    <parent link="bottom_link"/>
    <child link="caster_wheel_link"/>
    <origin rpy="0 0 0" xyz="0.16 0 -0.04"/>
    <axis xyz="1 1 1"/>
  </joint>
  <inertial>
    <mass value="1"/>
    <inertia ixx="0.00064" ixy="0.0" ixz="0.0" iyy="0.00064" iyz="0.0" izz="0.00064"/>
  </inertial>
  <!-- Wheels -->
  <!-- ~~~~~~ -->
  <!-- JOINTS -->
  <!-- ~~~~~~ -->
  <joint name="pig_joint" type="fixed">
    <parent link="bottom_link"/>
    <child link="body_link"/>
    <origin rpy="0 0 0" xyz="0.02 0 0.20"/>
  </joint>
  <inertial>
    <origin rpy="0 0 0" xyz="0.02 0 0.20"/>
    <mass value="1"/>
    <inertia ixx="0.0054666666666666665" ixy="0.0" ixz="0.0" iyy="0.011866666666666668" iyz="0.0" izz="0.010666666666666666"/>
    <!-- <inertia ixx="${(m/12) * (size[2]*size[2] + size[0]*size[0])}" ixy="0.0" ixz="0.0" iyy="${(m/12) * (size[1]*size[1] + size[0]*size[0])}" iyz="0.0" izz="${(m/12) * (size[1]*size[1] + size[2]*size[2])}"/> -->
  </inertial>
  <joint name="head_joint" type="fixed">
    <parent link="body_link"/>
    <child link="head_link"/>
    <origin rpy="0 0 0" xyz="0.20 0 0.04"/>
  </joint>
  <inertial>
    <origin rpy="0 0 0" xyz="0.20 0 0.04"/>
    <mass value="1"/>
    <inertia ixx="0.004266666666666667" ixy="0.0" ixz="0.0" iyy="0.004266666666666667" iyz="0.0" izz="0.004266666666666667"/>
    <!-- <inertia ixx="${(m/12) * (size[2]*size[2] + size[0]*size[0])}" ixy="0.0" ixz="0.0" iyy="${(m/12) * (size[1]*size[1] + size[0]*size[0])}" iyz="0.0" izz="${(m/12) * (size[1]*size[1] + size[2]*size[2])}"/> -->
  </inertial>
  <joint name="nose_joint" type="fixed">
    <parent link="head_link"/>
    <child link="nose_link"/>
    <origin rpy="0 0 0" xyz="0.09 0 -0.03"/>
  </joint>
  <inertial>
    <origin rpy="0 0 0" xyz="0.09 0 -0.03"/>
    <mass value="1"/>
    <inertia ixx="0.0008333333333333333" ixy="0.0" ixz="0.0" iyy="0.0005666666666666667" iyz="0.0" izz="0.0003333333333333333"/>
    <!-- <inertia ixx="${(m/12) * (size[2]*size[2] + size[0]*size[0])}" ixy="0.0" ixz="0.0" iyy="${(m/12) * (size[1]*size[1] + size[0]*size[0])}" iyz="0.0" izz="${(m/12) * (size[1]*size[1] + size[2]*size[2])}"/> -->
  </inertial>
  <link name="front_right_leg">
    <visual>
      <geometry>
        <box size="0.08 0.08 0.12"/>
      </geometry>
      <material name="Pink">
        <color rgba="0.859 0.318 0.318 1.0"/>
      </material>
    </visual>
    <collision>
      <geometry>
        <box size="0.08 0.08 0.12"/>
      </geometry>
    </collision>
  </link>
  <joint name="front_right_leg_joint" type="fixed">
    <parent link="body_link"/>
    <child link="front_right_leg"/>
    <origin rpy="0 0 0" xyz="0.1 -0.06 -0.14"/>
  </joint>
  <inertial>
    <origin rpy="0 0 0" xyz="0.1 -0.06 -0.14"/>
    <mass value="1"/>
    <inertia ixx="0.0017333333333333333" ixy="0.0" ixz="0.0" iyy="0.0010666666666666667" iyz="0.0" izz="0.0017333333333333333"/>
    <!-- <inertia ixx="${(m/12) * (size[2]*size[2] + size[0]*size[0])}" ixy="0.0" ixz="0.0" iyy="${(m/12) * (size[1]*size[1] + size[0]*size[0])}" iyz="0.0" izz="${(m/12) * (size[1]*size[1] + size[2]*size[2])}"/> -->
  </inertial>
  <link name="front_left_leg">
    <visual>
      <geometry>
        <box size="0.08 0.08 0.12"/>
      </geometry>
      <material name="Pink">
        <color rgba="0.859 0.318 0.318 1.0"/>
      </material>
    </visual>
    <collision>
      <geometry>
        <box size="0.08 0.08 0.12"/>
      </geometry>
    </collision>
  </link>
  <joint name="front_left_leg_joint" type="fixed">
    <parent link="body_link"/>
    <child link="front_left_leg"/>
    <origin rpy="0 0 0" xyz="0.1 0.06 -0.14"/>
  </joint>
  <inertial>
    <origin rpy="0 0 0" xyz="0.1 0.06 -0.14"/>
    <mass value="1"/>
    <inertia ixx="0.0017333333333333333" ixy="0.0" ixz="0.0" iyy="0.0010666666666666667" iyz="0.0" izz="0.0017333333333333333"/>
    <!-- <inertia ixx="${(m/12) * (size[2]*size[2] + size[0]*size[0])}" ixy="0.0" ixz="0.0" iyy="${(m/12) * (size[1]*size[1] + size[0]*size[0])}" iyz="0.0" izz="${(m/12) * (size[1]*size[1] + size[2]*size[2])}"/> -->
  </inertial>
  <link name="back_right_leg">
    <visual>
      <geometry>
        <box size="0.08 0.08 0.12"/>
      </geometry>
      <material name="Pink">
        <color rgba="0.859 0.318 0.318 1.0"/>
      </material>
    </visual>
    <collision>
      <geometry>
        <box size="0.08 0.08 0.12"/>
      </geometry>
    </collision>
  </link>
  <joint name="back_right_leg_joint" type="fixed">
    <parent link="body_link"/>
    <child link="back_right_leg"/>
    <origin rpy="0 0 0" xyz="-0.14 -0.06 -0.14"/>
  </joint>
  <inertial>
    <origin rpy="0 0 0" xyz="-0.14 -0.06 -0.14"/>
    <mass value="1"/>
    <inertia ixx="0.0017333333333333333" ixy="0.0" ixz="0.0" iyy="0.0010666666666666667" iyz="0.0" izz="0.0017333333333333333"/>
    <!-- <inertia ixx="${(m/12) * (size[2]*size[2] + size[0]*size[0])}" ixy="0.0" ixz="0.0" iyy="${(m/12) * (size[1]*size[1] + size[0]*size[0])}" iyz="0.0" izz="${(m/12) * (size[1]*size[1] + size[2]*size[2])}"/> -->
  </inertial>
  <link name="back_left_leg">
    <visual>
      <geometry>
        <box size="0.08 0.08 0.12"/>
      </geometry>
      <material name="Pink">
        <color rgba="0.859 0.318 0.318 1.0"/>
      </material>
    </visual>
    <collision>
      <geometry>
        <box size="0.08 0.08 0.12"/>
      </geometry>
    </collision>
  </link>
  <joint name="back_left_leg_joint" type="fixed">
    <parent link="body_link"/>
    <child link="back_left_leg"/>
    <origin rpy="0 0 0" xyz="-0.14 0.06 -0.14"/>
  </joint>
  <inertial>
    <origin rpy="0 0 0" xyz="-0.14 0.06 -0.14"/>
    <mass value="1"/>
    <inertia ixx="0.0017333333333333333" ixy="0.0" ixz="0.0" iyy="0.0010666666666666667" iyz="0.0" izz="0.0017333333333333333"/>
    <!-- <inertia ixx="${(m/12) * (size[2]*size[2] + size[0]*size[0])}" ixy="0.0" ixz="0.0" iyy="${(m/12) * (size[1]*size[1] + size[0]*size[0])}" iyz="0.0" izz="${(m/12) * (size[1]*size[1] + size[2]*size[2])}"/> -->
  </inertial>
  <link name="left_pupil">
    <visual>
      <geometry>
        <box size="0.0001 0.02 0.02"/>
      </geometry>
      <material name="Black">
        <color rgba="0 0 0 1"/>
      </material>
    </visual>
  </link>
  <joint name="left_pupil_joint" type="fixed">
    <parent link="head_link"/>
    <child link="left_pupil"/>
    <origin rpy="0 0 0" xyz="0.0801 -0.07 0.01"/>
  </joint>
  <link name="right_pupil">
    <visual>
      <geometry>
        <box size="0.0001 0.02 0.02"/>
      </geometry>
      <material name="Black">
        <color rgba="0 0 0 1"/>
      </material>
    </visual>
  </link>
  <joint name="right_pupil_joint" type="fixed">
    <parent link="head_link"/>
    <child link="right_pupil"/>
    <origin rpy="0 0 0" xyz="0.0801 0.07 0.01"/>
  </joint>
  <link name="left_eyeball">
    <visual>
      <geometry>
        <box size="0.0001 0.02 0.02"/>
      </geometry>
      <material name="White">
        <color rgba="1 1 1 1"/>
      </material>
    </visual>
  </link>
  <joint name="left_eyeball_joint" type="fixed">
    <parent link="head_link"/>
    <child link="left_eyeball"/>
    <origin rpy="0 0 0" xyz="0.0801 -0.05 0.01"/>
  </joint>
  <link name="right_eyeball">
    <visual>
      <geometry>
        <box size="0.0001 0.02 0.02"/>
      </geometry>
      <material name="White">
        <color rgba="1 1 1 1"/>
      </material>
    </visual>
  </link>
  <joint name="right_eyeball_joint" type="fixed">
    <parent link="head_link"/>
    <child link="right_eyeball"/>
    <origin rpy="0 0 0" xyz="0.0801 0.05 0.01"/>
  </joint>
  <link name="left_nostril">
    <visual>
      <geometry>
        <box size="0.0001 0.02 0.02"/>
      </geometry>
      <material name="Brown">
        <color rgba="0.4 0.08 0.07 1"/>
      </material>
    </visual>
  </link>
  <joint name="left_nostril_joint" type="fixed">
    <parent link="head_link"/>
    <child link="left_nostril"/>
    <origin rpy="0 0 0" xyz="0.1001 -0.03 -0.03"/>
  </joint>
  <link name="right_nostril">
    <visual>
      <geometry>
        <box size="0.0001 0.02 0.02"/>
      </geometry>
      <material name="Brown">
        <color rgba="0.4 0.08 0.07 1"/>
      </material>
    </visual>
  </link>
  <joint name="right_nostril_joint" type="fixed">
    <parent link="head_link"/>
    <child link="right_nostril"/>
    <origin rpy="0 0 0" xyz="0.1001 0.03 -0.03"/>
  </joint>
  <link name="right_side">
    <visual>
      <geometry>
        <box size="0.48 0.03 0.12"/>
      </geometry>
      <material name="Wood">
        <color rgba="0.58 0.46 0.18 1.0"/>
      </material>
    </visual>
    <collision>
      <geometry>
        <box size="0.48 0.03 0.12"/>
      </geometry>
    </collision>
  </link>
  <joint name="right_side_joint" type="fixed">
    <parent link="bottom_link"/>
    <child link="right_side"/>
    <origin rpy="0 0 0" xyz="0 -0.175 0.07"/>
  </joint>
  <inertial>
    <origin rpy="0 0 0" xyz="0 0 0"/>
    <mass value="1"/>
    <inertia ixx="0.0012749999999999999" ixy="0.0" ixz="0.0" iyy="0.019275" iyz="0.0" izz="0.020399999999999998"/>
    <!-- <inertia ixx="${(m/12) * (size[2]*size[2] + size[0]*size[0])}" ixy="0.0" ixz="0.0" iyy="${(m/12) * (size[1]*size[1] + size[0]*size[0])}" iyz="0.0" izz="${(m/12) * (size[1]*size[1] + size[2]*size[2])}"/> -->
  </inertial>
  <link name="left_side">
    <visual>
      <geometry>
        <box size="0.48 0.03 0.12"/>
      </geometry>
      <material name="Wood">
        <color rgba="0.58 0.46 0.18 1.0"/>
      </material>
    </visual>
    <collision>
      <geometry>
        <box size="0.48 0.03 0.12"/>
      </geometry>
    </collision>
  </link>
  <joint name="left_side_joint" type="fixed">
    <parent link="bottom_link"/>
    <child link="left_side"/>
    <origin rpy="0 0 0" xyz="0 0.175 0.07"/>
  </joint>
  <inertial>
    <origin rpy="0 0 0" xyz="0 0 0"/>
    <mass value="1"/>
    <inertia ixx="0.0012749999999999999" ixy="0.0" ixz="0.0" iyy="0.019275" iyz="0.0" izz="0.020399999999999998"/>
    <!-- <inertia ixx="${(m/12) * (size[2]*size[2] + size[0]*size[0])}" ixy="0.0" ixz="0.0" iyy="${(m/12) * (size[1]*size[1] + size[0]*size[0])}" iyz="0.0" izz="${(m/12) * (size[1]*size[1] + size[2]*size[2])}"/> -->
  </inertial>
  <link name="front_side">
    <visual>
      <geometry>
        <box size="0.03 0.32 0.12"/>
      </geometry>
      <material name="Wood">
        <color rgba="0.58 0.46 0.18 1.0"/>
      </material>
    </visual>
    <collision>
      <geometry>
        <box size="0.03 0.32 0.12"/>
      </geometry>
    </collision>
  </link>
  <joint name="front_side_joint" type="fixed">
    <parent link="bottom_link"/>
    <child link="front_side"/>
    <origin rpy="0 0 0" xyz="0.255 0 0.07"/>
  </joint>
  <inertial>
    <origin rpy="0 0 0" xyz="0 0 0"/>
    <mass value="1"/>
    <inertia ixx="0.009733333333333333" ixy="0.0" ixz="0.0" iyy="0.008608333333333332" iyz="0.0" izz="0.0012749999999999999"/>
    <!-- <inertia ixx="${(m/12) * (size[2]*size[2] + size[0]*size[0])}" ixy="0.0" ixz="0.0" iyy="${(m/12) * (size[1]*size[1] + size[0]*size[0])}" iyz="0.0" izz="${(m/12) * (size[1]*size[1] + size[2]*size[2])}"/> -->
  </inertial>
  <link name="back_side">
    <visual>
      <geometry>
        <box size="0.03 0.32 0.12"/>
      </geometry>
      <material name="Wood">
        <color rgba="0.58 0.46 0.18 1.0"/>
      </material>
    </visual>
    <collision>
      <geometry>
        <box size="0.03 0.32 0.12"/>
      </geometry>
    </collision>
  </link>
  <joint name="back_side_joint" type="fixed">
    <parent link="bottom_link"/>
    <child link="back_side"/>
    <origin rpy="0 0 0" xyz="-0.255 0 0.07"/>
  </joint>
  <inertial>
    <origin rpy="0 0 0" xyz="0 0 0"/>
    <mass value="1"/>
    <inertia ixx="0.009733333333333333" ixy="0.0" ixz="0.0" iyy="0.008608333333333332" iyz="0.0" izz="0.0012749999999999999"/>
    <!-- <inertia ixx="${(m/12) * (size[2]*size[2] + size[0]*size[0])}" ixy="0.0" ixz="0.0" iyy="${(m/12) * (size[1]*size[1] + size[0]*size[0])}" iyz="0.0" izz="${(m/12) * (size[1]*size[1] + size[2]*size[2])}"/> -->
  </inertial>
  <link name="right_paddle">
    <visual>
      <geometry>
        <box size="0.02 0.04 0.32"/>
      </geometry>
      <material name="Wood">
        <color rgba="0.52 0.42 0.18 1.0"/>
      </material>
    </visual>
    <collision>
      <geometry>
        <box size="0.02 0.04 0.32"/>
      </geometry>
    </collision>
  </link>
  <link name="right_paddle_plate">
    <visual>
      <geometry>
        <box size="0.02 0.10 0.14"/>
      </geometry>
      <material name="Wood">
        <color rgba="0.46 0.36 0.10 1.0"/>
      </material>
    </visual>
    <collision>
      <geometry>
        <box size="0.02 0.10 0.14"/>
      </geometry>
    </collision>
  </link>
  <joint name="right_paddle_plate_joint" type="fixed">
    <parent link="right_paddle"/>
    <child link="right_paddle_plate"/>
    <origin rpy="0 0 0" xyz="0.02 0 0.14"/>
  </joint>
  <inertial>
    <origin rpy="0 0 0" xyz="0.02 0 0.14"/>
    <mass value="1"/>
    <inertia ixx="0.002466666666666667" ixy="0.0" ixz="0.0" iyy="0.0008666666666666667" iyz="0.0" izz="0.001666666666666667"/>
    <!-- <inertia ixx="${(m/12) * (size[2]*size[2] + size[0]*size[0])}" ixy="0.0" ixz="0.0" iyy="${(m/12) * (size[1]*size[1] + size[0]*size[0])}" iyz="0.0" izz="${(m/12) * (size[1]*size[1] + size[2]*size[2])}"/> -->
  </inertial>
  <joint name="right_paddle_joint" type="fixed">
    <parent link="right_side"/>
    <child link="right_paddle"/>
    <origin rpy="2.0 0.2 -1.8" xyz="0.08 0.025 0.08"/>
  </joint>
  <inertial>
    <origin rpy="2.0 0.2 -1.8" xyz="0.08 0.025 0.08"/>
    <mass value="1"/>
    <inertia ixx="0.008666666666666666" ixy="0.0" ixz="0.0" iyy="0.00016666666666666666" iyz="0.0" izz="0.008566666666666667"/>
    <!-- <inertia ixx="${(m/12) * (size[2]*size[2] + size[0]*size[0])}" ixy="0.0" ixz="0.0" iyy="${(m/12) * (size[1]*size[1] + size[0]*size[0])}" iyz="0.0" izz="${(m/12) * (size[1]*size[1] + size[2]*size[2])}"/> -->
  </inertial>
  <link name="left_paddle">
    <visual>
      <geometry>
        <box size="0.02 0.04 0.32"/>
      </geometry>
      <material name="Wood">
        <color rgba="0.52 0.42 0.18 1.0"/>
      </material>
    </visual>
    <collision>
      <geometry>
        <box size="0.02 0.04 0.32"/>
      </geometry>
    </collision>
  </link>
  <link name="left_paddle_plate">
    <visual>
      <geometry>
        <box size="0.02 0.10 0.14"/>
      </geometry>
      <material name="Wood">
        <color rgba="0.46 0.36 0.10 1.0"/>
      </material>
    </visual>
    <collision>
      <geometry>
        <box size="0.02 0.10 0.14"/>
      </geometry>
    </collision>
  </link>
  <joint name="left_paddle_plate_joint" type="fixed">
    <parent link="left_paddle"/>
    <child link="left_paddle_plate"/>
    <origin rpy="0 0 0" xyz="0.02 0 0.14"/>
  </joint>
  <inertial>
    <origin rpy="0 0 0" xyz="0.02 0 0.14"/>
    <mass value="1"/>
    <inertia ixx="0.002466666666666667" ixy="0.0" ixz="0.0" iyy="0.0008666666666666667" iyz="0.0" izz="0.001666666666666667"/>
    <!-- <inertia ixx="${(m/12) * (size[2]*size[2] + size[0]*size[0])}" ixy="0.0" ixz="0.0" iyy="${(m/12) * (size[1]*size[1] + size[0]*size[0])}" iyz="0.0" izz="${(m/12) * (size[1]*size[1] + size[2]*size[2])}"/> -->
  </inertial>
  <joint name="left_paddle_joint" type="fixed">
    <parent link="left_side"/>
    <child link="left_paddle"/>
    <origin rpy="-2.0 0.2 1.8" xyz="0.08 -0.025 0.08"/>
  </joint>
  <inertial>
    <origin rpy="-2.0 0.2 1.8" xyz="0.08 -0.025 0.08"/>
    <mass value="1"/>
    <inertia ixx="0.008666666666666666" ixy="0.0" ixz="0.0" iyy="0.00016666666666666666" iyz="0.0" izz="0.008566666666666667"/>
    <!-- <inertia ixx="${(m/12) * (size[2]*size[2] + size[0]*size[0])}" ixy="0.0" ixz="0.0" iyy="${(m/12) * (size[1]*size[1] + size[0]*size[0])}" iyz="0.0" izz="${(m/12) * (size[1]*size[1] + size[2]*size[2])}"/> -->
  </inertial>
  <link name="right_wheel_link">
    <visual>
      <geometry>
        <cylinder length="0.03" radius="0.08"/>
      </geometry>
      <material name="Dark Wood">
        <color rgba="0.46 0.36 0.10 1.0"/>
      </material>
    </visual>
    <collision>
      <geometry>
        <cylinder length="0.03" radius="0.08"/>
      </geometry>
    </collision>
  </link>
  <joint name="right_wheel_joint" type="continuous">
    <parent link="bottom_link"/>
    <child link="right_wheel_link"/>
    <origin rpy="-1.5707963267948966 0 0" xyz="-0.12 -0.21 0"/>
    <axis xyz="0 0 1"/>
  </joint>
  <inertial>
    <origin rpy="-1.5707963267948966 0 0" xyz="-0.12 -0.21 0"/>
    <mass value="1"/>
    <inertia ixx="0.0016749999999999998" ixy="0" ixz="0" iyy="0.0016749999999999998" iyz="0" izz="0.0032"/>
  </inertial>
  <link name="left_wheel_link">
    <visual>
      <geometry>
        <cylinder length="0.03" radius="0.08"/>
      </geometry>
      <material name="Dark Wood">
        <color rgba="0.46 0.36 0.10 1.0"/>
      </material>
    </visual>
    <collision>
      <geometry>
        <cylinder length="0.03" radius="0.08"/>
      </geometry>
    </collision>
  </link>
  <joint name="left_wheel_joint" type="continuous">
    <parent link="bottom_link"/>
    <child link="left_wheel_link"/>
    <origin rpy="-1.5707963267948966 0 0" xyz="-0.12 0.21 0"/>
    <axis xyz="0 0 1"/>
  </joint>
  <inertial>
    <origin rpy="-1.5707963267948966 0 0" xyz="-0.12 0.21 0"/>
    <mass value="1"/>
    <inertia ixx="0.0016749999999999998" ixy="0" ixz="0" iyy="0.0016749999999999998" iyz="0" izz="0.0032"/>
  </inertial>
</robot>
